2025-05-29 15:14:04 - INFO - Файловый логгер успешно настроен
2025-05-29 15:14:04 - INFO - Запуск системы...
2025-05-29 15:14:04 - ERROR - Файл процесса не найден: processes/adc.py
2025-05-29 15:14:04 - ERROR - Файл процесса не найден: processes/fft.py
2025-05-29 15:14:04 - ERROR - Файл процесса не найден: processes/str3_saver.py
2025-05-29 15:14:04 - INFO - Процесс 'hello' запущен (PID: 18077)
2025-05-29 15:14:04 - INFO - Текущие процессы: {'hello': 'Running'}
2025-05-29 15:14:04 - INFO - UDP-сервер запущен и слушает порт 30000
2025-05-29 15:14:04 - INFO - UDP-сервер запущен
2025-05-29 15:14:07 - INFO - Получен сигнал KeyboardInterrupt, остановка системы...
2025-05-29 15:14:07 - INFO - Процесс 'hello' (PID: 18077) остановлен
2025-05-29 15:14:07 - INFO - UDP-сервер остановлен
2025-05-29 15:14:07 - INFO - Система остановлена
2025-05-29 15:15:25 - INFO - Файловый логгер успешно настроен
2025-05-29 15:15:25 - INFO - Запуск системы...
2025-05-29 15:15:25 - INFO - Текущие процессы: {}
2025-05-29 15:15:25 - INFO - UDP-сервер запущен и слушает порт 30000
2025-05-29 15:15:25 - INFO - UDP-сервер запущен
2025-05-29 15:15:31 - INFO - Получен сигнал KeyboardInterrupt, остановка системы...
2025-05-29 15:15:31 - INFO - UDP-сервер остановлен
2025-05-29 15:15:31 - INFO - Система остановлена
2025-05-29 15:16:42 - INFO - Файловый логгер успешно настроен
2025-05-29 15:16:42 - INFO - Запуск системы...
2025-05-29 15:16:42 - INFO - Процесс: %s adc не активирован
2025-05-29 15:16:42 - INFO - Процесс: %s fft не активирован
2025-05-29 15:16:42 - INFO - Процесс: %s str3_saver не активирован
2025-05-29 15:16:42 - INFO - Процесс: %s hello не активирован
2025-05-29 15:16:42 - INFO - Текущие процессы: {}
2025-05-29 15:16:42 - INFO - UDP-сервер запущен и слушает порт 30000
2025-05-29 15:16:42 - INFO - UDP-сервер запущен
2025-05-29 15:17:02 - INFO - Получен сигнал KeyboardInterrupt, остановка системы...
2025-05-29 15:17:02 - INFO - UDP-сервер остановлен
2025-05-29 15:17:02 - INFO - Система остановлена
2025-05-29 15:17:03 - INFO - Файловый логгер успешно настроен
2025-05-29 15:17:03 - INFO - Запуск системы...
2025-05-29 15:17:03 - INFO - Текущие процессы: {}
2025-05-29 15:17:03 - INFO - UDP-сервер запущен и слушает порт 30000
2025-05-29 15:17:03 - INFO - UDP-сервер запущен
2025-05-29 15:17:21 - INFO - Получен сигнал KeyboardInterrupt, остановка системы...
2025-05-29 15:17:21 - INFO - UDP-сервер остановлен
2025-05-29 15:17:59 - INFO - Файловый логгер успешно настроен
2025-05-29 15:17:59 - INFO - Запуск системы...
2025-05-29 15:17:59 - ERROR - Файл процесса не найден: processes/adc.py
2025-05-29 15:17:59 - ERROR - Файл процесса не найден: processes/fft.py
2025-05-29 15:17:59 - ERROR - Файл процесса не найден: processes/str3_saver.py
2025-05-29 15:17:59 - INFO - Процесс 'hello' запущен (PID: 18338)
2025-05-29 15:17:59 - INFO - Текущие процессы: {'hello': 'Running'}
2025-05-29 15:17:59 - INFO - UDP-сервер запущен и слушает порт 30000
2025-05-29 15:17:59 - INFO - UDP-сервер запущен
2025-05-29 15:18:01 - INFO - Получен сигнал KeyboardInterrupt, остановка системы...
2025-05-29 15:18:01 - INFO - Процесс 'hello' (PID: 18338) остановлен
2025-05-29 15:18:01 - INFO - UDP-сервер остановлен
2025-05-29 15:18:01 - INFO - Система остановлена
2025-05-29 15:19:48 - INFO - Файловый логгер успешно настроен
2025-05-29 15:19:48 - INFO - Запуск системы...
2025-05-29 15:19:48 - INFO - Текущие процессы: {}
2025-05-29 15:19:48 - INFO - UDP-сервер запущен и слушает порт 30000
2025-05-29 15:19:48 - INFO - UDP-сервер запущен
2025-05-29 15:19:51 - INFO - Получен сигнал KeyboardInterrupt, остановка системы...
2025-05-29 15:19:51 - INFO - UDP-сервер остановлен
2025-05-29 15:19:51 - INFO - Система остановлена
2025-05-29 15:20:12 - INFO - Файловый логгер успешно настроен
2025-05-29 15:20:12 - INFO - Запуск системы...
2025-05-29 15:20:12 - INFO - Текущие процессы: {}
2025-05-29 15:20:12 - INFO - UDP-сервер запущен и слушает порт 30000
2025-05-29 15:20:12 - INFO - UDP-сервер запущен
2025-05-29 15:20:16 - INFO - Получен сигнал KeyboardInterrupt, остановка системы...
2025-05-29 15:20:16 - INFO - UDP-сервер остановлен
2025-05-29 15:20:16 - INFO - Система остановлена
2025-05-29 15:20:24 - INFO - Файловый логгер успешно настроен
2025-05-29 15:20:24 - INFO - Запуск системы...
2025-05-29 15:20:24 - ERROR - Файл процесса не найден: processes/adc.py
2025-05-29 15:20:24 - ERROR - Файл процесса не найден: processes/fft.py
2025-05-29 15:20:24 - ERROR - Файл процесса не найден: processes/str3_saver.py
2025-05-29 15:20:24 - INFO - Процесс 'hello' запущен (PID: 18465)
2025-05-29 15:20:24 - INFO - Текущие процессы: {'hello': 'Running'}
2025-05-29 15:20:24 - INFO - UDP-сервер запущен и слушает порт 30000
2025-05-29 15:20:24 - INFO - UDP-сервер запущен
2025-05-29 15:20:46 - INFO - Файловый логгер успешно настроен
2025-05-29 15:20:46 - INFO - Запуск системы...
2025-05-29 15:20:46 - ERROR - Файл процесса не найден: processes/adc.py
2025-05-29 15:20:46 - ERROR - Файл процесса не найден: processes/fft.py
2025-05-29 15:20:46 - ERROR - Файл процесса не найден: processes/str3_saver.py
2025-05-29 15:20:46 - INFO - Процесс 'hello' запущен (PID: 18539)
2025-05-29 15:20:46 - INFO - Текущие процессы: {'hello': 'Running'}
2025-05-29 15:20:46 - ERROR - Ошибка при запуске сервера: [Errno 98] Address already in use
2025-05-29 15:20:46 - ERROR - Критическая ошибка: [Errno 98] Address already in use
Traceback (most recent call last):
  File "/home/orangepi/po/main.py", line 58, in <module>
    server.start()
  File "/home/orangepi/po/main_process/network_module.py", line 24, in start
    self.socket.bind((self.host, self.port))
OSError: [Errno 98] Address already in use
2025-05-29 15:20:46 - INFO - Процесс 'hello' (PID: 18539) остановлен
2025-05-29 15:20:46 - INFO - UDP-сервер остановлен
2025-05-29 15:20:46 - INFO - Система остановлена
2025-05-29 15:20:57 - INFO - Файловый логгер успешно настроен
2025-05-29 15:20:57 - INFO - Запуск системы...
2025-05-29 15:20:57 - ERROR - Файл процесса не найден: processes/adc.py
2025-05-29 15:20:57 - ERROR - Файл процесса не найден: processes/fft.py
2025-05-29 15:20:57 - ERROR - Файл процесса не найден: processes/str3_saver.py
2025-05-29 15:20:57 - INFO - Процесс 'hello' запущен (PID: 18581)
2025-05-29 15:20:57 - INFO - Текущие процессы: {'hello': 'Running'}
2025-05-29 15:20:57 - ERROR - Ошибка при запуске сервера: [Errno 98] Address already in use
2025-05-29 15:20:57 - ERROR - Критическая ошибка: [Errno 98] Address already in use
Traceback (most recent call last):
  File "/home/orangepi/po/main.py", line 58, in <module>
    server.start()
  File "/home/orangepi/po/main_process/network_module.py", line 24, in start
    self.socket.bind((self.host, self.port))
OSError: [Errno 98] Address already in use
2025-05-29 15:20:57 - INFO - Процесс 'hello' (PID: 18581) остановлен
2025-05-29 15:20:57 - INFO - UDP-сервер остановлен
2025-05-29 15:20:57 - INFO - Система остановлена
2025-05-29 15:21:13 - INFO - Файловый логгер успешно настроен
2025-05-29 15:21:13 - INFO - Запуск системы...
2025-05-29 15:21:13 - ERROR - Файл процесса не найден: processes/adc.py
2025-05-29 15:21:13 - ERROR - Файл процесса не найден: processes/fft.py
2025-05-29 15:21:13 - ERROR - Файл процесса не найден: processes/str3_saver.py
2025-05-29 15:21:13 - INFO - Процесс 'hello' запущен (PID: 18641)
2025-05-29 15:21:13 - INFO - Текущие процессы: {'hello': 'Running'}
2025-05-29 15:21:13 - ERROR - Ошибка при запуске сервера: [Errno 98] Address already in use
2025-05-29 15:21:13 - ERROR - Критическая ошибка: [Errno 98] Address already in use
Traceback (most recent call last):
  File "/home/orangepi/po/main.py", line 58, in <module>
    server.start()
  File "/home/orangepi/po/main_process/network_module.py", line 24, in start
    self.socket.bind((self.host, self.port))
OSError: [Errno 98] Address already in use
2025-05-29 15:21:13 - INFO - Процесс 'hello' (PID: 18641) остановлен
2025-05-29 15:21:13 - INFO - UDP-сервер остановлен
2025-05-29 15:21:13 - INFO - Система остановлена
2025-05-29 15:21:46 - INFO - Файловый логгер успешно настроен
2025-05-29 15:21:46 - INFO - Запуск системы...
2025-05-29 15:21:46 - ERROR - Файл процесса не найден: processes/adc.py
2025-05-29 15:21:46 - ERROR - Файл процесса не найден: processes/fft.py
2025-05-29 15:21:46 - ERROR - Файл процесса не найден: processes/str3_saver.py
2025-05-29 15:21:46 - INFO - Процесс 'hello' запущен (PID: 18685)
2025-05-29 15:21:46 - INFO - Текущие процессы: {'hello': 'Running'}
2025-05-29 15:21:46 - ERROR - Ошибка при запуске сервера: [Errno 98] Address already in use
2025-05-29 15:21:46 - ERROR - Критическая ошибка: [Errno 98] Address already in use
Traceback (most recent call last):
  File "/home/orangepi/po/main.py", line 58, in <module>
    server.start()
  File "/home/orangepi/po/main_process/network_module.py", line 24, in start
    self.socket.bind((self.host, self.port))
OSError: [Errno 98] Address already in use
2025-05-29 15:21:46 - INFO - Процесс 'hello' (PID: 18685) остановлен
2025-05-29 15:21:46 - INFO - UDP-сервер остановлен
2025-05-29 15:21:46 - INFO - Система остановлена
2025-05-29 15:23:49 - INFO - Файловый логгер успешно настроен
2025-05-29 15:23:49 - INFO - Запуск системы...
2025-05-29 15:23:49 - ERROR - Файл процесса не найден: processes/adc.py
2025-05-29 15:23:49 - ERROR - Файл процесса не найден: processes/fft.py
2025-05-29 15:23:49 - ERROR - Файл процесса не найден: processes/str3_saver.py
2025-05-29 15:23:49 - INFO - Процесс 'hello' запущен (PID: 18982)
2025-05-29 15:23:49 - INFO - Текущие процессы: {'hello': 'Running'}
2025-05-29 15:23:49 - ERROR - Ошибка при запуске сервера: [Errno 98] Address already in use
2025-05-29 15:23:49 - ERROR - Критическая ошибка: [Errno 98] Address already in use
Traceback (most recent call last):
  File "/home/orangepi/po/main.py", line 58, in <module>
    server.start()
  File "/home/orangepi/po/main_process/network_module.py", line 24, in start
    self.socket.bind((self.host, self.port))
OSError: [Errno 98] Address already in use
2025-05-29 15:23:49 - INFO - Процесс 'hello' (PID: 18982) остановлен
2025-05-29 15:23:49 - INFO - UDP-сервер остановлен
2025-05-29 15:23:49 - INFO - Система остановлена
2025-05-29 15:24:26 - INFO - Файловый логгер успешно настроен
2025-05-29 15:24:26 - INFO - Запуск системы...
2025-05-29 15:24:26 - ERROR - Файл процесса не найден: processes/adc.py
2025-05-29 15:24:26 - ERROR - Файл процесса не найден: processes/fft.py
2025-05-29 15:24:26 - ERROR - Файл процесса не найден: processes/str3_saver.py
2025-05-29 15:24:26 - INFO - Процесс 'hello' запущен (PID: 19185)
2025-05-29 15:24:26 - INFO - Текущие процессы: {'hello': 'Running'}
2025-05-29 15:24:26 - ERROR - Ошибка при запуске сервера: [Errno 98] Address already in use
2025-05-29 15:24:26 - ERROR - Критическая ошибка: [Errno 98] Address already in use
Traceback (most recent call last):
  File "/home/orangepi/po/main.py", line 58, in <module>
    server.start()
  File "/home/orangepi/po/main_process/network_module.py", line 24, in start
    self.socket.bind((self.host, self.port))
OSError: [Errno 98] Address already in use
2025-05-29 15:24:26 - INFO - Процесс 'hello' (PID: 19185) остановлен
2025-05-29 15:24:26 - INFO - UDP-сервер остановлен
2025-05-29 15:24:26 - INFO - Система остановлена
2025-05-29 15:24:40 - INFO - Файловый логгер успешно настроен
2025-05-29 15:24:40 - INFO - Запуск системы...
2025-05-29 15:24:40 - ERROR - Файл процесса не найден: processes/adc.py
2025-05-29 15:24:40 - ERROR - Файл процесса не найден: processes/fft.py
2025-05-29 15:24:40 - ERROR - Файл процесса не найден: processes/str3_saver.py
2025-05-29 15:24:40 - INFO - Процесс 'hello' запущен (PID: 19236)
2025-05-29 15:24:40 - INFO - Текущие процессы: {'hello': 'Running'}
2025-05-29 15:24:40 - ERROR - Ошибка при запуске сервера: [Errno 98] Address already in use
2025-05-29 15:24:40 - ERROR - Критическая ошибка: [Errno 98] Address already in use
Traceback (most recent call last):
  File "/home/orangepi/po/main.py", line 58, in <module>
    server.start()
  File "/home/orangepi/po/main_process/network_module.py", line 24, in start
    self.socket.bind((self.host, self.port))
OSError: [Errno 98] Address already in use
2025-05-29 15:24:40 - INFO - Процесс 'hello' (PID: 19236) остановлен
2025-05-29 15:24:40 - INFO - UDP-сервер остановлен
2025-05-29 15:24:40 - INFO - Система остановлена
2025-05-29 15:25:15 - INFO - Файловый логгер успешно настроен
2025-05-29 15:25:15 - INFO - Запуск системы...
2025-05-29 15:25:15 - ERROR - Файл процесса не найден: processes/adc.py
2025-05-29 15:25:15 - ERROR - Файл процесса не найден: processes/fft.py
2025-05-29 15:25:15 - ERROR - Файл процесса не найден: processes/str3_saver.py
2025-05-29 15:25:15 - INFO - Процесс 'hello' запущен (PID: 19425)
2025-05-29 15:25:15 - INFO - Текущие процессы: {'hello': 'Running'}
2025-05-29 15:25:15 - ERROR - Ошибка при запуске сервера: [Errno 98] Address already in use
2025-05-29 15:25:15 - ERROR - Критическая ошибка: [Errno 98] Address already in use
Traceback (most recent call last):
  File "/home/orangepi/po/main.py", line 58, in <module>
    server.start()
  File "/home/orangepi/po/main_process/network_module.py", line 24, in start
    self.socket.bind((self.host, self.port))
OSError: [Errno 98] Address already in use
2025-05-29 15:25:15 - INFO - Процесс 'hello' (PID: 19425) остановлен
2025-05-29 15:25:15 - INFO - UDP-сервер остановлен
2025-05-29 15:25:15 - INFO - Система остановлена
2025-05-29 15:26:17 - INFO - Файловый логгер успешно настроен
2025-05-29 15:26:17 - INFO - Запуск системы...
2025-05-29 15:26:17 - ERROR - Файл процесса не найден: processes/adc.py
2025-05-29 15:26:17 - ERROR - Файл процесса не найден: processes/fft.py
2025-05-29 15:26:17 - ERROR - Файл процесса не найден: processes/str3_saver.py
2025-05-29 15:26:17 - INFO - Процесс 'hello' запущен (PID: 19730)
2025-05-29 15:26:17 - INFO - Текущие процессы: {'hello': 'Running'}
2025-05-29 15:26:17 - INFO - UDP-сервер запущен и слушает порт 30000
2025-05-29 15:26:17 - INFO - UDP-сервер запущен
2025-05-29 15:26:27 - INFO - Получен сигнал KeyboardInterrupt, остановка системы...
2025-05-29 15:26:27 - INFO - Процесс 'hello' (PID: 19730) остановлен
2025-05-29 15:26:27 - INFO - UDP-сервер остановлен
2025-05-29 15:26:27 - INFO - Система остановлена
